# Analysis Error Report

An error occurred during analysis: 1 validation error for ChatOpenAI
  Value error, Did not find openai_api_key, please add an environment variable `OPENAI_API_KEY` which contains it, or pass `openai_api_key` as a named parameter. [type=value_error, input_value={'model_name': 'gpt-4o', ...ne, 'http_client': None}, input_type=dict]
    For further information visit https://errors.pydantic.dev/2.11/v/value_error
